<?xml version="1.0"?>
<robot name="robot_arm">

  <material name="blue">
    <color rgba="0 0 0.8 1"/>
  </material>
  <material name="grey">
    <color rgba="0.5 0.5 0.5 1"/>
  </material>
  <material name="red">
    <color rgba="0.8 0 0 1"/>
  </material>

  <link name="base_link">
    <visual>
      <geometry>
        <box size="0.2 0.2 0.05"/>
      </geometry>
      <material name="blue"/>
    </visual>
  </link>

  <joint name="joint1" type="revolute">
    <parent link="base_link"/>
    <child link="link1"/>
    <origin xyz="0 0 0.025" rpy="0 0 0"/>
    <axis xyz="0 0 1"/>
    <limit lower="-3.14" upper="3.14" effort="100" velocity="1.0"/>
  </joint>

  <link name="link1">
    <visual>
      <origin xyz="0 0 0.15" rpy="0 0 0"/>
      <geometry>
        <cylinder radius="0.05" length="0.3"/>
      </geometry>
      <material name="grey"/>
    </visual>
  </link>

  <joint name="joint2" type="revolute">
    <parent link="link1"/>
    <child link="link2"/>
    <origin xyz="0 0 0.3" rpy="0 0 0"/>
    <axis xyz="0 1 0"/>
    <limit lower="-1.57" upper="1.57" effort="100" velocity="1.0"/>
  </joint>

  <link name="link2">
    <visual>
      <origin xyz="0 0 0.125" rpy="0 0 0"/>
      <geometry>
        <cylinder radius="0.04" length="0.25"/>
      </geometry>
      <material name="grey"/>
    </visual>
  </link>

  <joint name="joint3" type="revolute">
    <parent link="link2"/>
    <child link="link3"/>
    <origin xyz="0 0 0.25" rpy="0 0 0"/>
    <axis xyz="0 1 0"/>
    <limit lower="-1.57" upper="1.57" effort="100" velocity="1.0"/>
  </joint>

  <link name="link3">
    <visual>
      <origin xyz="0 0 0.1" rpy="0 0 0"/>
      <geometry>
        <cylinder radius="0.03" length="0.2"/>
      </geometry>
      <material name="red"/>
    </visual>
  </link>

</robot>
